<?xml version="1.0"?>
<robot name="inspectorbot">
  
  <!-- Import Rviz colors -->
  <material name="Black">
    <color rgba="0.0 0.0 0.0 1.0"/>
  </material>
  <material name="Blue">
    <color rgba="0.0 0.0 0.8 1.0"/>
  </material>
  <material name="Green">
    <color rgba="0.0 0.8 0.0 1.0"/>
  </material>
  <material name="Grey">
    <color rgba="0.4 0.4 0.4 1.0"/>
  </material>
  <material name="Orange">
    <color rgba="1.0 0.423529411765 0.0392156862745 1.0"/>
  </material>
  <material name="Brown">
    <color rgba="0.870588235294 0.811764705882 0.764705882353 1.0"/>
  </material>
  <material name="Red">
    <color rgba="0.8 0.0 0.0 1.0"/>
  </material>
  <material name="White">
    <color rgba="1.0 1.0 1.0 1.0"/>
  </material>

<!--   <link name="bug"/>

  <joint name="world_to_main_body_link_joint" type="floating">
    <origin rpy="0 0 0" xyz="0 0 0.0"/>
    <parent link="bug"/>
    <child link="main_body_link"/>
  </joint> -->

  <link name="main_body_link">
    <visual>
      <geometry>
        <box size = "0.76 0.46 0.55"/>
      </geometry>
       <origin rpy="0 0 0" xyz="0 0 0.405"/>
       <material name="white"/>
    </visual>
    <collision>
      <geometry>
        <box size = "0.76 0.46 0.55"/>
      </geometry>
       <origin rpy="0 0 0" xyz="0 0 0.405"/>
    </collision>    
    <inertial>
      <mass value="50"/>
      <inertia ixx="2.14" ixy="0.0" ixz="0.0" iyy="3.67" iyz="0.0" izz="3.29"/>
    </inertial>    
  </link>

  <joint name="main_body_to_front_right_shaft" type="fixed">
    <parent link="main_body_link"/>
    <child link="front_right_shaft_link"/>
    <origin rpy="-1.57075 0 0" xyz="0.220 -0.255 0.200"/>
  </joint>

  <link name="front_right_shaft_link">
    <visual>
      <geometry>
        <cylinder length="0.05" radius="0.02"/>
      </geometry>
        <material name="blue"/>
    </visual>
    <collision>
      <geometry>
        <cylinder length="0.05" radius="0.02"/>
      </geometry>
    </collision>    
  </link>

  <joint name="front_right_shaft_to_front_right_wheel" type="continuous">
    <parent link="front_right_shaft_link"/>
    <child link="front_right_wheel_link"/>
    <origin rpy="0 0 0" xyz="0 0 -0.100"/>
    <axis xyz="0 0 1"/>
  </joint>

  <link name="front_right_wheel_link">
    <visual>
      <geometry>
        <cylinder length="0.15" radius="0.20"/>
      </geometry>
       <material name="black"/>
    </visual>
    <collision>
      <geometry>
        <cylinder length="0.15" radius="0.20"/>
      </geometry>
    </collision>   
    <inertial>
      <mass value="5"/>
      <inertia ixx="0.02" ixy="0.0" ixz="0.0" iyy="0.02" iyz="0.0" izz="0.04"/>
    </inertial>         
  </link>

  <joint name="main_body_to_back_right_shaft" type="fixed">
    <parent link="main_body_link"/>
    <child link="back_right_shaft_link"/>
    <origin rpy="-1.57075 0 0" xyz="-0.220 -0.255 0.200"/>
  </joint>    

  <link name="back_right_shaft_link">
    <visual>
      <geometry>
        <cylinder length="0.05" radius="0.02"/>
      </geometry>
        <material name="blue"/>
    </visual>
    <collision>
      <geometry>
        <cylinder length="0.05" radius="0.02"/>
      </geometry>
    </collision>    
  </link>

  <joint name="back_right_shaft_to_backt_right_wheel" type="continuous">
    <parent link="back_right_shaft_link"/>
    <child link="back_right_wheel_link"/>
    <origin rpy="0 0 0" xyz="0 0 -0.100"/>
    <axis xyz="0 0 1"/>
  </joint>

  <link name="back_right_wheel_link">
    <visual>
      <geometry>
        <cylinder length="0.15" radius="0.20"/>
      </geometry>
       <material name="black"/>
    </visual>
    <collision>
      <geometry>
        <cylinder length="0.15" radius="0.20"/>
      </geometry>
    </collision>   
    <inertial>
      <mass value="5"/>
      <inertia ixx="0.02" ixy="0.0" ixz="0.0" iyy="0.02" iyz="0.0" izz="0.04"/>
    </inertial>              
  </link>

  <joint name="main_body_to_front_left_shaft" type="fixed">
    <parent link="main_body_link"/>
    <child link="front_left_shaft_link"/>
    <origin rpy="1.57075 0 0" xyz="0.220 0.255 0.200"/>
  </joint>

  <link name="front_left_shaft_link">
    <visual>
      <geometry>
        <cylinder length="0.05" radius="0.02"/>
      </geometry>
        <material name="blue"/>
    </visual>
    <collision>
      <geometry>
        <cylinder length="0.05" radius="0.02"/>
      </geometry>
    </collision>    
  </link>

  <joint name="front_left_shaft_to_front_left_wheel" type="continuous">
    <parent link="front_left_shaft_link"/>
    <child link="front_left_wheel_link"/>
    <origin rpy="0 0 0" xyz="0 0 -0.100"/>
    <axis xyz="0 0 -1"/>
  </joint>

  <link name="front_left_wheel_link">
    <visual>
      <geometry>
        <cylinder length="0.15" radius="0.20"/>
      </geometry>
       <material name="black"/>
    </visual>
    <collision>
      <geometry>
        <cylinder length="0.15" radius="0.20"/>
      </geometry>
    </collision>  
    <inertial>
      <mass value="5"/>
      <inertia ixx="0.02" ixy="0.0" ixz="0.0" iyy="0.02" iyz="0.0" izz="0.04"/>
    </inertial>               
  </link>

  <joint name="main_body_to_back_left_shaft" type="fixed">
    <parent link="main_body_link"/>
    <child link="back_left_shaft_link"/>
    <origin rpy="1.57075 0 0" xyz="-0.220 0.255 0.200"/>
  </joint>

  <link name="back_left_shaft_link">
    <visual>
      <geometry>
        <cylinder length="0.05" radius="0.02"/>
      </geometry>
        <material name="blue"/>
    </visual>
    <collision>
      <geometry>
        <cylinder length="0.05" radius="0.02"/>
      </geometry>
    </collision>    
  </link>

  <joint name="back_left_shaft_to_back_left_wheel" type="continuous">
    <parent link="back_left_shaft_link"/>
    <child link="back_left_wheel_link"/>
    <origin rpy="0 0 0" xyz="0 0 -0.100"/>
    <axis xyz="0 0 -1"/>
  </joint>

  <link name="back_left_wheel_link">
    <visual>
      <geometry>
        <cylinder length="0.15" radius="0.20"/>
      </geometry>
       <material name="black"/>
    </visual>
    <collision>
      <geometry>
        <cylinder length="0.15" radius="0.20"/>
      </geometry>
    </collision>    
    <inertial>
      <mass value="5"/>
      <inertia ixx="0.02" ixy="0.0" ixz="0.0" iyy="0.02" iyz="0.0" izz="0.04"/>
    </inertial>             
  </link>  

<!--   <gazebo>
    <plugin name="gazebo_ros_control" filename="libgazebo_ros_control.so">
      <robotNamespace>/</robotNamespace>
    </plugin>
  </gazebo> -->

</robot>
